<?xml version="1.0" encoding="UTF-8"?>
<!DOCTYPE xml>
<robot xmlns:xacro="http://www.ros.org/wiki/xacro" name="wx250s">

  <xacro:property name="B" value="0.07025" />
  <xacro:property name="B_radius" value="0.15" />
  <xacro:property name="L1" value="0.04" />
  <xacro:property name="L1radius" value="0.10" />
  <xacro:property name="L2" value="0.25" />
  <xacro:property name="L2radius" value="0.05" />
  <xacro:property name="Lfixed" value="0.10" />
  <xacro:property name="Lfixedradius" value="0.05" />
  <xacro:property name="L3" value="0.17155" />
  <xacro:property name="L3radius" value="0.05" />
  <xacro:property name="L4" value="0.07845" />
  <xacro:property name="L4radius" value="0.055" />
  <xacro:property name="L5" value="0.065" />
  <xacro:property name="L5radius" value="0.05" />
  <xacro:property name="L6" value="0.10915" />
  <xacro:property name="L6radius" value="0.055" />
  <xacro:property name="eesize" value="0.05" />
  <xacro:property name="J1MIN" value="${-pi}" />
  <xacro:property name="J1MAX" value="${pi}" />
  <xacro:property name="J2MIN" value="${(-108/180)*pi}" />
  <xacro:property name="J2MAX" value="${(114/180)*pi}" />
  <xacro:property name="J3MIN" value="${(-123/180)*pi}" />
  <xacro:property name="J3MAX" value="${(92/180)*pi}" />
  <xacro:property name="J4MIN" value="${-pi}" />
  <xacro:property name="J4MAX" value="${pi}" />
  <xacro:property name="J5MIN" value="${(-100/180)*pi}" />
  <xacro:property name="J5MAX" value="${(123/180)*pi}" />
  <xacro:property name="J6MIN" value="${-pi}" />
  <xacro:property name="J6MAX" value="${pi}" />

  <material name="blue">
    <color rgba="0.2 0.4 0.65 1" />
  </material>

  <material name="yellow">
    <color rgba="1 0.85 0 1" />
  </material>

  <link name="world" />

  <link name="base_link">
    <visual name="base_link">
      <origin xyz="0 0 ${B/2}" />
      <geometry>
        <cylinder radius="${B_radius}" length="${B}" />
      </geometry>
      <material name="blue" />
    </visual>
  </link>

  <link name="link1">
    <visual name="link1">
      <origin xyz="0 0 ${L1/2}" />
      <geometry>
        <cylinder radius="${L1radius}" length="${L1}" />
      </geometry>
      <material name="blue" />
    </visual>
  </link>

  <link name="link2">
    <visual name="link2">
      <origin xyz="0 0 ${L2/2}" />
      <geometry>
        <cylinder radius="${L2radius}" length="${L2}" />
      </geometry>
      <material name="blue" />
    </visual>
  </link>

  <link name="linkfixed">
    <visual name="linkfixed">
      <origin rpy="${pi/2} 0 0" xyz="0 0 0" />
      <geometry>
        <cylinder radius="${Lfixedradius}" length="${Lfixed}" />
      </geometry>
      <material name="blue" />
    </visual>
  </link>

  <link name="link3">
    <visual name="link3">
      <origin rpy="0 ${pi/2} 0" xyz="${L3/2} 0 0 " />
      <geometry>
        <cylinder radius="${L3radius}" length="${L3}" />
      </geometry>
      <material name="blue" />
    </visual>
  </link>

  <link name="link4">
    <visual name="link4">
      <origin rpy="0 ${pi/2} 0" xyz="${L4/2} 0 0 " />
      <geometry>
        <cylinder radius="${L4radius}" length="${L4}" />
      </geometry>
      <material name="blue" />
    </visual>
  </link>

  <link name="link5">
    <visual name="link5">
      <origin rpy="0 ${pi/2} 0" xyz="${L5/2} 0 0 " />
      <geometry>
        <cylinder radius="${L5radius}" length="${L5}" />
      </geometry>
      <material name="blue" />
    </visual>
  </link>

  <link name="link6">
    <visual name="link6">
      <origin rpy="0 ${pi/2} 0" xyz="${L6/2} 0 0 " />
      <geometry>
        <cylinder radius="${L6radius}" length="${L6}" />
      </geometry>
      <material name="blue" />
    </visual>
  </link>

  <link name="ee">
    <visual name="ee">
      <origin xyz="0 0 0" />
      <geometry>
        <box size="${eesize} ${eesize} ${eesize}" />
      </geometry>
      <material name="yellow" />
    </visual>
  </link>

  <joint name="base_in_world" type="fixed">
    <parent link="world" />
    <child link="base_link" />
    <origin xyz="0 0 0" />
  </joint>

  <joint name="joint1" type="revolute">
    <parent link="base_link" />
    <child link="link1" />
    <origin rpy="0 0 0" xyz="0 0 ${B}" />
    <axis xyz="0 0 1" />
    <limit lower="${J1MIN}" upper="${J1MAX}" effort="1" velocity="1" />
  </joint>

  <joint name="joint2" type="revolute">
    <parent link="link1" />
    <child link="link2" />
    <origin rpy="0 0 0" xyz="0 0 ${L1}" />
    <axis xyz="0 1 0" />
    <limit lower="${J2MIN}" upper="${J2MAX}" effort="1" velocity="1" />
  </joint>

  <joint name="jointfixed" type="fixed">
    <parent link="link2" />
    <child link="linkfixed" />
    <origin rpy="0 0 0" xyz="0 0 ${L2}" />
  </joint>

  <joint name="joint3" type="revolute">
    <parent link="linkfixed" />
    <child link="link3" />
    <origin rpy="0 0 0" xyz="0.05 0 0" />
    <axis xyz="0 1 0" />
    <limit lower="${J3MIN}" upper="${J3MAX}" effort="1" velocity="1" />
  </joint>

  <joint name="joint4" type="revolute">
    <parent link="link3" />
    <child link="link4" />
    <origin rpy="0 0 0" xyz="${L3} 0 0" />
    <axis xyz="1 0 0" />
    <limit lower="${J4MIN}" upper="${J4MAX}" effort="1" velocity="1" />
  </joint>

  <joint name="joint5" type="revolute">
    <parent link="link4" />
    <child link="link5" />
    <origin rpy="0 0 0" xyz="${L4} 0 0" />
    <axis xyz="0 1 0" />
    <limit lower="${J5MIN}" upper="${J5MAX}" effort="1" velocity="1" />
  </joint>

  <joint name="joint6" type="revolute">
    <parent link="link5" />
    <child link="link6" />
    <origin rpy="0 0 0" xyz="${L5} 0 0" />
    <axis xyz="1 0 0" />
    <limit lower="${J6MIN}" upper="${J6MAX}" effort="1" velocity="1" />
  </joint>

  <joint name="ee_in_link3" type="fixed">
    <parent link="link6" />
    <child link="ee" />
    <origin xyz="${L6} 0 0" rpy="0 0 0" />
  </joint>

</robot>
